Workbook

Sheet Sheet1
A3: Product | B3: Sales | C3: Region | D3: Discount Eligible | F3: Check if Sales > 100 | G3: Test if Region = 'East' | H3: Check if Sales > 100 AND Region = 'East' | I3: Check if Sales < 100 OR Region = 'West' | J3: Check if Sales > 100 AND < 200 | K3: Check if Sales < 100 OR Region = North | L3: Check if Region = East AND Discount Eligible = 'Yes' | M3: Return Pass/Fail if Sales > 150 AND Region = East | N3: Categorize Region as 'Main' if East, otherwise 'Other' | O3: Check if Sales > 100 AND (Region = East OR Region = West) | P3: Mark Review if Sales < 100 OR Region = North | Q3: Apply 10% discount if Sales > 150 AND Region = East | R3: Check if three conditions hold (Sales > 100, Region = East, Discount Eligible = Yes) | S3: Mark 'Priority' if Sales > 200 OR (Sales > 100 AND Region = East) | T3: Flag mid-tier sales (Sales > 100 and < 200, but not East) | U3: Nested AND inside OR for discount rules | V3: Use nested IFs for tiered logic
A4: A | B4: 120 | C4: East | D4: Yes | F4: =IF(B4>100,TRUE,FALSE) -> TRUE | G4: =IF(C4="East",TRUE,FALSE) -> TRUE | H4: =IF(AND(B4>100, C4="East"), TRUE, FALSE) -> TRUE | I4: =IF(OR(B4<100, C4="West"), TRUE, FALSE) -> FALSE | J4: =IF(AND(B4>100,B4<200),TRUE,FALSE) -> TRUE | K4: =IF(OR(B4<100,C4="North"),TRUE,FALSE) -> FALSE | L4: =IF(AND(C4="East",D4="Yes"),TRUE,FALSE) -> TRUE | M4: =IF(AND(B4>150,C4="East"),"Pass","Fail") -> Fail | N4: =IF(C4="East","Main","Other") -> Main | O4: =IF(AND(OR(B4>100,C4="East",C4="West")),TRUE,FALSE) -> TRUE | P4: =IF(OR(B4<100,C4="North"),"Review","Ok") -> Ok | Q4: =IF(AND(B4>150,C4="East"),B4*0.9,) -> 0 | R4: =IF(AND(B4>100,C4="East",D4="Yes"),TRUE,FALSE) -> TRUE | S4: =IF(OR(B4>200,AND(B4>100,C4="East")),"Priority","Normal") -> Priority | T4: =IF(AND(B4>100,B4<200,C4<>"East"),TRUE,FALSE) -> FALSE | U4: =OR(AND(B4>150, C4="East"), AND(B4>200, C4="West")) -> FALSE | V4: =IF(AND(B2>200,C2="East"),"High",IF(AND(B2>100,C2="West"),"Medium","Low")) -> Low
A5: B | B5: 90 | C5: West | D5: No | F5: =IF(B5>100,TRUE,FALSE) -> FALSE | G5: =IF(C5="East",TRUE,FALSE) -> FALSE | H5: =IF(AND(B5>100, C5="East"), TRUE, FALSE) -> FALSE | I5: =IF(OR(B5<100, C5="West"), TRUE, FALSE) -> TRUE | J5: =IF(AND(B5>100,B5<200),TRUE,FALSE) -> FALSE | K5: =IF(OR(B5<100,C5="North"),TRUE,FALSE) -> TRUE | L5: =IF(AND(C5="East",D5="Yes"),TRUE,FALSE) -> FALSE | M5: =IF(AND(B5>150,C5="East"),"Pass","Fail") -> Fail | N5: =IF(C5="East","Main","Other") -> Other | O5: =IF(AND(OR(B5>100,C5="East",C5="West")),TRUE,FALSE) -> TRUE | P5: =IF(OR(B5<100,C5="North"),"Review","Ok") -> Review | Q5: =IF(AND(B5>150,C5="East"),B5*0.9,) -> 0 | R5: =IF(AND(B5>100,C5="East",D5="Yes"),TRUE,FALSE) -> FALSE | S5: =IF(OR(B5>200,AND(B5>100,C5="East")),"Priority","Normal") -> Normal | T5: =IF(AND(B5>100,B5<200,C5<>"East"),TRUE,FALSE) -> FALSE | U5: =OR(AND(B5>150, C5="East"), AND(B5>200, C5="West")) -> FALSE | V5: =IF(AND(B3>200,C3="East"),"High",IF(AND(B3>100,C3="West"),"Medium","Low")) -> Low
A6: C | B6: 200 | C6: East | D6: Yes | F6: =IF(B6>100,TRUE,FALSE) -> TRUE | G6: =IF(C6="East",TRUE,FALSE) -> TRUE | H6: =IF(AND(B6>100, C6="East"), TRUE, FALSE) -> TRUE | I6: =IF(OR(B6<100, C6="West"), TRUE, FALSE) -> FALSE | J6: =IF(AND(B6>100,B6<200),TRUE,FALSE) -> FALSE | K6: =IF(OR(B6<100,C6="North"),TRUE,FALSE) -> FALSE | L6: =IF(AND(C6="East",D6="Yes"),TRUE,FALSE) -> TRUE | M6: =IF(AND(B6>150,C6="East"),"Pass","Fail") -> Pass | N6: =IF(C6="East","Main","Other") -> Main | O6: =IF(AND(OR(B6>100,C6="East",C6="West")),TRUE,FALSE) -> TRUE | P6: =IF(OR(B6<100,C6="North"),"Review","Ok") -> Ok | Q6: =IF(AND(B6>150,C6="East"),B6*0.9,) -> 180 | R6: =IF(AND(B6>100,C6="East",D6="Yes"),TRUE,FALSE) -> TRUE | S6: =IF(OR(B6>200,AND(B6>100,C6="East")),"Priority","Normal") -> Priority | T6: =IF(AND(B6>100,B6<200,C6<>"East"),TRUE,FALSE) -> FALSE | U6: =OR(AND(B6>150, C6="East"), AND(B6>200, C6="West")) -> TRUE | V6: =IF(AND(B4>200,C4="East"),"High",IF(AND(B4>100,C4="West"),"Medium","Low")) -> Low
A7: D | B7: 150 | C7: North | D7: No | F7: =IF(B7>100,TRUE,FALSE) -> TRUE | G7: =IF(C7="East",TRUE,FALSE) -> FALSE | H7: =IF(AND(B7>100, C7="East"), TRUE, FALSE) -> FALSE | I7: =IF(OR(B7<100, C7="West"), TRUE, FALSE) -> FALSE | J7: =IF(AND(B7>100,B7<200),TRUE,FALSE) -> TRUE | K7: =IF(OR(B7<100,C7="North"),TRUE,FALSE) -> TRUE | L7: =IF(AND(C7="East",D7="Yes"),TRUE,FALSE) -> FALSE | M7: =IF(AND(B7>150,C7="East"),"Pass","Fail") -> Fail | N7: =IF(C7="East","Main","Other") -> Other | O7: =IF(AND(OR(B7>100,C7="East",C7="West")),TRUE,FALSE) -> TRUE | P7: =IF(OR(B7<100,C7="North"),"Review","Ok") -> Review | Q7: =IF(AND(B7>150,C7="East"),B7*0.9,) -> 0 | R7: =IF(AND(B7>100,C7="East",D7="Yes"),TRUE,FALSE) -> FALSE | S7: =IF(OR(B7>200,AND(B7>100,C7="East")),"Priority","Normal") -> Normal | T7: =IF(AND(B7>100,B7<200,C7<>"East"),TRUE,FALSE) -> TRUE | U7: =OR(AND(B7>150, C7="East"), AND(B7>200, C7="West")) -> FALSE | V7: =IF(AND(B5>200,C5="East"),"High",IF(AND(B5>100,C5="West"),"Medium","Low")) -> Low
A8: E | B8: 80 | C8: East | D8: Yes | F8: =IF(B8>100,TRUE,FALSE) -> FALSE | G8: =IF(C8="East",TRUE,FALSE) -> TRUE | H8: =IF(AND(B8>100, C8="East"), TRUE, FALSE) -> FALSE | I8: =IF(OR(B8<100, C8="West"), TRUE, FALSE) -> TRUE | J8: =IF(AND(B8>100,B8<200),TRUE,FALSE) -> FALSE | K8: =IF(OR(B8<100,C8="North"),TRUE,FALSE) -> TRUE | L8: =IF(AND(C8="East",D8="Yes"),TRUE,FALSE) -> TRUE | M8: =IF(AND(B8>150,C8="East"),"Pass","Fail") -> Fail | N8: =IF(C8="East","Main","Other") -> Main | O8: =IF(AND(OR(B8>100,C8="East",C8="West")),TRUE,FALSE) -> TRUE | P8: =IF(OR(B8<100,C8="North"),"Review","Ok") -> Review | Q8: =IF(AND(B8>150,C8="East"),B8*0.9,) -> 0 | R8: =IF(AND(B8>100,C8="East",D8="Yes"),TRUE,FALSE) -> FALSE | S8: =IF(OR(B8>200,AND(B8>100,C8="East")),"Priority","Normal") -> Normal | T8: =IF(AND(B8>100,B8<200,C8<>"East"),TRUE,FALSE) -> FALSE | U8: =OR(AND(B8>150, C8="East"), AND(B8>200, C8="West")) -> FALSE | V8: =IF(AND(B6>200,C6="East"),"High",IF(AND(B6>100,C6="West"),"Medium","Low")) -> Low

Sheet Identifying the least revenue
A1: Product ID | B1: Product Name | C1: Category | D1: Units Sold | E1: Price Per Unit | F1: Total Revenue
A2: P001 | B2: Smartphone A | C2: Electronics | D2: 150 | E2: 10000 | F2: 1500000
A3: P002 | B3: Headphones C | C3: Electronics | D3: 300 | E3: 1500 | F3: 450000
A4: P003 | B4: T-shirt D | C4: Fashion | D4: 500 | E4: 500 | F4: 250000
A5: P004 | B5: Book F | C5: Books | D5: 1000 | E5: 200 | F5: 200000
A6: P005 | B6: Toy H | C6: Toys | D6: 150 | E6: 1000 | F6: 150000
A8: Answer | B8: =MIN(F2:F6) -> 150000

Sheet Urban Company
A1: Customer Name | B1: Address | C1: Cleaned Customer Name | D1: Cleaned Address
A2: Aman Sharma | B2: 123,Mg Road, Delhi | C2: =TRIM(A2) -> Aman Sharma | D2: =TRIM(B2) -> 123,Mg Road, Delhi
A3: Priya Verma | B3: 456, Brigade Road, Bangalore | C3: =TRIM(A3) -> Priya Verma | D3: =TRIM(B3) -> 456, Brigade Road, Bangalore
A4: Rajesh Kumar | B4: 789, Anna Salai, Chennai | C4: =TRIM(A4) -> Rajesh Kumar | D4: =TRIM(B4) -> 789, Anna Salai, Chennai
A5: Sunita Reddy | B5: 1010, Park Street, Kolkata | C5: =TRIM(A5) -> Sunita Reddy | D5: =TRIM(B5) -> 1010, Park Street, Kolkata
A6: Vijay Singh | B6: 1111, Banjara Hills, Hyderabad | C6: =TRIM(A6) -> Vijay Singh | D6: =TRIM(B6) -> 1111, Banjara Hills, Hyderabad

Sheet Meta Ad Revenue Analysis
A1: State | B1: Ad Clicks | C1: Revenue | D1: Corrected revenue
A2: Maharashtra | B2: 1200 | C2: 10000 | D2: =IFERROR(C2,500) -> 10000
A3: Karnataka | B3: 800 | C3: 7000 | D3: =IFERROR(C3,500) -> 7000
A4: Tamil Nadu | B4: 950 | C4: #DIV/0! | D4: =IFERROR(C4,500) -> 500
A5: Kerala | B5: 1100 | C5: 8500 | D5: =IFERROR(C5,500) -> 8500

Sheet Subscription Billing Time
A1: Customer Name | B1: Hours | C1: Minutes | D1: Billing Time
A2: Reliance | B2: 10 | C2: 30 | D2: =TIME(B2,C2,0) -> 0.4375
A3: TCS | B3: 12 | C3: 45 | D3: =TIME(B3,C3,0) -> 0.53125
A4: Infosys | B4: 14 | C4: 15 | D4: =TIME(B4,C4,0) -> 0.59375
A5: HDFC Bank | B5: 16 | C5: 0 | D5: =TIME(B5,C5,0) -> 0.66666667
A6: ICICI Bank | B6: 18 | C6: 30 | D6: =TIME(B6,C6,0) -> 0.77083333

Sheet Converting Sales Data
A1: Seller ID | B1: Seller Name | C1: Sales Figure(Text) | D1: Sales Figure(Number)
A2: 101 | B2: Ram Trading Co. | C2: 10000 | D2: =_xlfn.NUMBERVALUE(C2) -> 10000
A3: 102 | B3: MAHESH Enterprises | C3: 15000 | D3: =_xlfn.NUMBERVALUE(C3) -> 15000
A4: 103 | B4: Vinayaka STORES | C4: 20000 | D4: =_xlfn.NUMBERVALUE(C4) -> 20000
A5: 104 | B5: Anand & Sons | C5: 25000 | D5: =_xlfn.NUMBERVALUE(C5) -> 25000
A6: 105 | B6: Shree Ganesh Mart | C6: 30000 | D6: =_xlfn.NUMBERVALUE(C6) -> 30000

Sheet Vehicle Price Analysis
A1: Vehicle Id | B1: Price (INR)
A2: V001 | B2: 350000
A3: V002 | B3: 450000
A4: V003 | B4: 300000
A5: V004 | B5: 500000
A6: V005 | B6: 600000
A7: V006 | B7: 700000
A8: V007 | B8: 550000
A9: V008 | B9: 400000
A10: V009 | B10: 380000
A11: V010 | B11: 620000
A14: 25th Percentile | B14: =QUARTILE(B2:B11,1) -> 385000
A15: 50th Percentile | B15: =QUARTILE(B2:B11,2) -> 475000
A16: 75th Percentile | B16: =QUARTILE(B2:B11,3) -> 587500

Sheet Customer Support Tickets
A1: Region | B1: Support Tickets Received
A2: North | B2: 150
A3: South | B3: 120
A4: East | B4: 100
A5: West | B5: 80
A6: Central | B6: 50
A8: Answer | B8: =SUM(B2:B6) -> 500

Sheet Calculating Revenue Loss
A1: Item Id | B1: Item Name | C1: Units Requested | D1: Units Available | E1: Price per Unit | F1: Revenue Loss
A2: 101 | B2: Denim Jacket | C2: 500 | D2: 300 | E2: 1500 | F2: =(C2-D2)*E2 -> 300000
A3: 102 | B3: Leather Boots | C3: 200 | D3: 200 | E3: 3500 | F3: =(C3-D3)*E3 -> 0
A4: 103 | B4: Summer Dress | C4: 450 | D4: 400 | E4: 1200 | F4: =(C4-D4)*E4 -> 60000
A5: 104 | B5: Casual Dress | C5: 600 | D5: 550 | E5: 800 | F5: =(C5-D5)*E5 -> 40000
A6: 105 | B6: Formal Trousers | C6: 300 | D6: 250 | E6: 2000 | F6: =(C6-D6)*E6 -> 100000

Sheet Analysis of Ad Campaign
A1: Campaign Name | B1: Impressions | C1: Clicks | D1: Conversions | E1: Cost | F1: Revenue | G1: Conversion Rate % | H1: Cost per Click (CPC) | I1: Return On Investment
A2: Campaign A | B2: 12500 | C2: 380 | D2: 25 | E2: 35000 | F2: 175000 | G2: =(D2/C2)*100 -> 6.5789474 | H2: =B2/C2 -> 32.894737 | I2: =((F2-E2)/E2)*100 -> 400
A3: Campaign B | B3: 9800 | C3: 290 | D3: 20 | E3: 28000 | F3: 168000 | G3: =(D3/C3)*100 -> 6.8965517 | H3: =B3/C3 -> 33.793103 | I3: =((F3-E3)/E3)*100 -> 500
A4: Campaign C | B4: 15000 | C4: 420 | D4: 30 | E4: 40000 | F4: 50000 | G4: =(D4/C4)*100 -> 7.1428571 | H4: =B4/C4 -> 35.714286 | I4: =((F4-E4)/E4)*100 -> 25
A5: Campaign D | B5: 8000 | C5: 250 | D5: 15 | E5: 22000 | F5: 44000 | G5: =(D5/C5)*100 -> 6 | H5: =B5/C5 -> 32 | I5: =((F5-E5)/E5)*100 -> 100
A6: Campaign E | B6: 20000 | C6: 600 | D6: 40 | E6: 50000 | F6: 100000 | G6: =(D6/C6)*100 -> 6.6666667 | H6: =B6/C6 -> 33.333333 | I6: =((F6-E6)/E6)*100 -> 100
A7: Campaign F | B7: 13500 | C7: 410 | D7: 28 | E7: 37000 | F7: 74000 | G7: =(D7/C7)*100 -> 6.8292683 | H7: =B7/C7 -> 32.926829 | I7: =((F7-E7)/E7)*100 -> 100
A8: Campaign G | B8: 11000 | C8: 320 | D8: 18 | E8: 30000 | F8: 40000 | G8: =(D8/C8)*100 -> 5.625 | H8: =B8/C8 -> 34.375 | I8: =((F8-E8)/E8)*100 -> 33.333333
A9: Campaign H | B9: 16500 | C9: 480 | D9: 35 | E9: 45000 | F9: 180000 | G9: =(D9/C9)*100 -> 7.2916667 | H9: =B9/C9 -> 34.375 | I9: =((F9-E9)/E9)*100 -> 300
A10: Campaign I | B10: 7500 | C10: 200 | D10: 12 | E10: 18000 | F10: 72000 | G10: =(D10/C10)*100 -> 6 | H10: =B10/C10 -> 37.5 | I10: =((F10-E10)/E10)*100 -> 300
A11: Campaign J | B11: 18000 | C11: 550 | D11: 45 | E11: 60000 | F11: 300000 | G11: =(D11/C11)*100 -> 8.1818182 | H11: =B11/C11 -> 32.727273 | I11: =((F11-E11)/E11)*100 -> 400
A15: Top Performing Campaign Based on ROI | E15: =INDEX(A2:A11,MATCH(MAX(I2:I11),I2:I11,0)) -> Campaign B
A16: Top Performing Campaign Based on Revnue | E16: =INDEX(A2:A11,MATCH(MAX(I2:I11),I2:I11,0)) -> Campaign B
A17: Least Performing Campaign Based on ROI | E17: =INDEX(A2:A11,MATCH(MIN(I2:I11),I2:I11,0)) -> Campaign C
A18: Least Performing Campaign Based on Revenue | E18: =INDEX(A2:A11,MATCH(MIN(F2:F11),F2:F11,0)) -> Campaign G

Sheet Tracking In-App Purchases
A1: Transaction ID | B1: User ID | C1: Amount Spent (In Rupees) | D1: Amount Spent Whole Number
A2: 12345 | B2: MG123 | C2: 198.5 | D2: =FLOOR(C2,1) -> 198
A3: 54321 | B3: MG456 | C3: 129.99 | D3: =FLOOR(C3,1) -> 129
A4: 67890 | B4: MG789 | C4: 499 | D4: =FLOOR(C4,1) -> 499
A5: 21098 | B5: MG012 | C5: 99.75 | D5: =FLOOR(C5,1) -> 99

Sheet Analyzing Customer Purchase (Zo
A1: Customer ID | B1: Jan | C1: Feb | D1: Mar | E1: Apr | F1: May | G1: Jun | H1: Jul | I1: Aug | J1: Sep | K1: Oct | L1: Nov | M1: Dec
A2: C001 | B2: 1200 | C2: 1300 | D2: 1250 | E2: 1400 | F2: 1500 | G2: 1450 | H2: 1550 | I2: 1600 | J2: 1650 | K2: 1700 | L2: 1750 | M2: 1800
A3: C002 | B3: 1000 | C3: 1100 | D3: 1050 | E3: 1150 | F3: 1200 | G3: 1250 | H3: 1300 | I3: 1350 | J3: 1400 | K3: 1450 | L3: 1500 | M3: 1550
A4: C003 | B4: 2000 | C4: 2100 | D4: 2050 | E4: 2150 | F4: 2200 | G4: 2250 | H4: 2300 | I4: 2350 | J4: 2400 | K4: 2450 | L4: 2500 | M4: 2550
A5: C004 | B5: 1500 | C5: 1600 | D5: 1550 | E5: 1650 | F5: 1700 | G5: 1750 | H5: 1800 | I5: 1850 | J5: 1900 | K5: 1950 | L5: 2000 | M5: 2050
A6: C005 | B6: 1100 | C6: 1200 | D6: 1150 | E6: 1250 | F6: 1300 | G6: 1350 | H6: 1400 | I6: 1450 | J6: 1500 | K6: 1550 | L6: 1600 | M6: 1650
A7: C006 | B7: 1800 | C7: 1900 | D7: 1850 | E7: 1950 | F7: 2000 | G7: 2050 | H7: 2100 | I7: 2150 | J7: 2200 | K7: 2250 | L7: 2300 | M7: 2350
A8: C007 | B8: 1300 | C8: 1400 | D8: 1350 | E8: 1450 | F8: 1500 | G8: 1550 | H8: 1600 | I8: 1650 | J8: 1700 | K8: 1750 | L8: 1800 | M8: 1850
A9: C008 | B9: 1700 | C9: 1800 | D9: 1750 | E9: 1850 | F9: 1900 | G9: 1950 | H9: 2000 | I9: 2050 | J9: 2100 | K9: 2150 | L9: 2200 | M9: 2250
A10: C009 | B10: 1400 | C10: 1500 | D10: 1450 | E10: 1550 | F10: 1600 | G10: 1650 | H10: 1700 | I10: 1750 | J10: 1800 | K10: 1850 | L10: 1900 | M10: 1950
A11: C010 | B11: 1600 | C11: 1700 | D11: 1650 | E11: 1750 | F11: 1800 | G11: 1850 | H11: 1900 | I11: 1950 | J11: 1950 | K11: 2050 | L11: 2100 | M11: 2150
A13: Standard Deviation | C13: =STDEV(B2:M11) -> 348.99215

Sheet Maximizing Ad Revenue (Google)
A1: Region | B1: Ad Type | C1: Revenue(INR)
A2: North | B2: Display Ads | C2: 1500000
A3: South | B3: Display Ads | C3: 1250000
A4: East | B4: Display Ads | C4: 1800000
A5: West | B5: Display Ads | C5: 1400000
A6: North | B6: Video Ads | C6: 2200000
A7: South | B7: Video Ads | C7: 2450000
A8: East | B8: Video Ads | C8: 2000000
A9: West | B9: Video Ads | C9: 2300000
A10: North | B10: Search Ads | C10: 3000000
A11: South | B11: Search Ads | C11: 2800000
A12: East | B12: Search Ads | C12: 2750000
A13: West | B13: Search Ads | C13: 3100000
A15: Answer | B15: {=INDEX(A2:A13,MATCH(MAX(IF(B2:B13="Display Ads",C2:C13)),C2:C13,0))} -> East | C15: {=INDEX(A2:A13,MATCH(MAX(IF(B2:B13="Video Ads",C2:C13)),C2:C13,0))} -> South
B16: {=INDEX(A2:A13,MATCH(MIN(IF(B2:B13="Display Ads",C2:C13)),C2:C13,0))} -> South | C16: {=INDEX(A2:A13,MATCH(MIN(IF(B2:B13="Video Ads",C2:C13)),C2:C13,0))} -> East

Sheet Randomly Assigning Discount 
A1: Customer Id | B1: Customer Name | C1: Discount Code | E1: Discount Code
A2: C001 | B2: Anil Kumar | C2: =CHOOSE(RANDBETWEEN(1,3),"10%","15%","20%") -> 15% | D2: =RAND() -> 0.82239993 | E2: =IF(D2<=0.33,"10%",IF(D2<=0.66,"15%","20%")) -> 20%
A3: C002 | B3: Priya Sharma | C3: =CHOOSE(RANDBETWEEN(1,3),"10%","15%","20%") -> 15% | D3: =RAND() -> 0.18354363 | E3: =IF(D3<=0.33,"10%",IF(D3<=0.66,"15%","20%")) -> 10%
A4: C003 | B4: Rohit Verma | C4: =CHOOSE(RANDBETWEEN(1,3),"10%","15%","20%") -> 15% | D4: =RAND() -> 0.4261416 | E4: =IF(D4<=0.33,"10%",IF(D4<=0.66,"15%","20%")) -> 15%
A5: C004 | B5: Sunita Rao | C5: =CHOOSE(RANDBETWEEN(1,3),"10%","15%","20%") -> 10% | D5: =RAND() -> 0.54236007 | E5: =IF(D5<=0.33,"10%",IF(D5<=0.66,"15%","20%")) -> 15%
A6: C005 | B6: Rajesh Singh | C6: =CHOOSE(RANDBETWEEN(1,3),"10%","15%","20%") -> 20% | D6: =RAND() -> 0.95710414 | E6: =IF(D6<=0.33,"10%",IF(D6<=0.66,"15%","20%")) -> 20%
A7: C006 | B7: Neha Gupta | C7: =CHOOSE(RANDBETWEEN(1,3),"10%","15%","20%") -> 15% | D7: =RAND() -> 0.57254336 | E7: =IF(D7<=0.33,"10%",IF(D7<=0.66,"15%","20%")) -> 15%
A8: C007 | B8: Manish Tiwari | C8: =CHOOSE(RANDBETWEEN(1,3),"10%","15%","20%") -> 15% | D8: =RAND() -> 0.43587734 | E8: =IF(D8<=0.33,"10%",IF(D8<=0.66,"15%","20%")) -> 15%
A9: C008 | B9: Kavita Patel | C9: =CHOOSE(RANDBETWEEN(1,3),"10%","15%","20%") -> 20% | D9: =RAND() -> 0.45937704 | E9: =IF(D9<=0.33,"10%",IF(D9<=0.66,"15%","20%")) -> 15%
A10: C009 | B10: Rakesh Mehra | C10: =CHOOSE(RANDBETWEEN(1,3),"10%","15%","20%") -> 15% | D10: =RAND() -> 0.26712928 | E10: =IF(D10<=0.33,"10%",IF(D10<=0.66,"15%","20%")) -> 10%
A11: C010 | B11: Pooja Joshi | C11: =CHOOSE(RANDBETWEEN(1,3),"10%","15%","20%") -> 10% | D11: =RAND() -> 0.54987349 | E11: =IF(D11<=0.33,"10%",IF(D11<=0.66,"15%","20%")) -> 15%

Sheet Identifying Income Batch Codes
A1: Batch Code | B1: Product Name | C1: Is Batch Code Valid
A2: SHMP-001234 | B2: SunSilk Smooth & Shiny Shampoo | C2: =IF(LEN(A2)=11,"Valid Code","Invalid Code") -> Valid Code | D2: =IFERROR(LEN(A2)<>11,"Invalid Code") -> FALSE
A3: SHMP-AB12345 | B3: Dove Nourishing Oil Care Shampoo | C3: =IF(LEN(A3)=11,"Valid Code","Invalid Code") -> Invalid Code | D3: =IFERROR(LEN(A3)<>11,"Invalid Code") -> TRUE
A4: SHMP-XY9999 | B4: Head & Shoulders Cool Menthol Shampoo | C4: =IF(LEN(A4)=11,"Valid Code","Invalid Code") -> Valid Code | D4: =IFERROR(LEN(A4)<>11,"Invalid Code") -> FALSE
A5: SHMP-123AA | B5: SunSilk Smooth Shampoo | C5: =IF(LEN(A5)=11,"Valid Code","Invalid Code") -> Invalid Code | D5: =IFERROR(LEN(A5)<>11,"Invalid Code") -> TRUE
A6: SHMP-123456789A | B6: Dove Basic Oil Care Shampoo | C6: =IF(LEN(A6)=11,"Valid Code","Invalid Code") -> Invalid Code | D6: =IFERROR(LEN(A6)<>11,"Invalid Code") -> TRUE
A7: SHMP-YYZZ1234 | B7: Head & Shoulders Quick Dry Shampoo | C7: =IF(LEN(A7)=11,"Valid Code","Invalid Code") -> Invalid Code | D7: =IFERROR(LEN(A7)<>11,"Invalid Code") -> TRUE

Sheet Analyzing Client Investment
A1: Client Investment Data
A2: Client ID | B2: Asset Type | C2: Investment Amount
A3: 1001 | B3: Stocks | C3: 50000
A4: 1001 | B4: Bonds | C4: 20000
A5: 1001 | B5: Real Estate | C5: 30000
A6: 1002 | B6: Stocks | C6: 70000
A7: 1002 | B7: Bonds | C7: 40000
A8: 1002 | B8: Mutual Funds | C8: 25000
A9: 1003 | B9: Real Estate | C9: 60000
A10: 1003 | B10: Stocks | C10: 50000
A11: 1003 | B11: Bonds | C11: 35000
A13: Client Summary
A14: Client Id | B14: Stocks | C14: Bonds | D14: Real Estate | E14: Mutual Funds | F14: Total Investment
A15: 1001 | B15: {=INDEX(C2:C11, MATCH(1, (A2:A11=A15)*(B2:B11=B14), 0))} -> 50000 | C15: {=INDEX(C2:C11, MATCH(1, (A2:A11=A15)*(B2:B11=C14), 0))} -> 20000 | D15: {=INDEX(C2:C11, MATCH(1, (A2:A11=A15)*(B2:B11=D14), 0))} -> 30000 | E15: {=INDEX(C2:C11, MATCH(1, (A2:A11=A15)*(B2:B11=E14), 0))} -> #N/A
A16: 1002 | B16: {=INDEX(C2:C11, MATCH(1, (A2:A11=A16)*(B2:B11=B14), 0))} -> 70000 | C16: {=INDEX(C2:C11, MATCH(1, (A2:A11=A16)*(B2:B11=C14), 0))} -> 40000 | D16: {=INDEX(C2:C11, MATCH(1, (A2:A11=A16)*(B2:B11=D14), 0))} -> #N/A | E16: {=INDEX(C2:C11, MATCH(1, (A2:A11=A16)*(B2:B11=E14), 0))} -> 25000
A17: 1003 | B17: {=INDEX(C2:C12, MATCH(1, (A2:A12=A17)*(B2:B12=B14), 0))} -> 50000 | C17: {=INDEX(C2:C11, MATCH(1, (A2:A11=A17)*(B2:B11=C14), 0))} -> 35000 | D17: {=INDEX(C2:C11, MATCH(1, (A2:A11=A17)*(B2:B11=D14), 0))} -> 60000 | E17: {=INDEX(C2:C12, MATCH(1, (A2:A12=A17)*(B3:B12=E14), 0))} -> #N/A
A19: Client Investment Calculator
A20: Client Id | B20: Asset Type | C20: Investment Amount
A21: 1003 | B21: Bonds | C21: =VLOOKUP(A21,A2:C11,3) -> 35000

Sheet Email Normalization 
A1: Email Address | B1: Normalized Email
A2: john.doe@gmail.com | B2: =SUBSTITUTE(LEFT(A2,FIND("@",A2)-1),".","") & MID(A2,FIND("@",A2),LEN(A2)) -> johndoe@gmail.com
A3: jane.smith@gmail.com | B3: =SUBSTITUTE(LEFT(A3,FIND("@",A3)-1),".","")& MID(A3,FIND("@",A3),LEN(A3)) -> janesmith@gmail.com
A4: j.ohndoe@gmail.com | B4: =SUBSTITUTE(LEFT(A4,FIND("@",A4)-1),".","")& MID(A4,FIND("@",A4),LEN(A4)) -> johndoe@gmail.com
A5: jan.e.sm.ith@gmail.com | B5: =SUBSTITUTE(LEFT(A5,FIND("@",A5)-1),".","")& MID(A5,FIND("@",A5),LEN(A5)) -> janesmith@gmail.com
A6: mark.parker@yahoo.com | B6: =SUBSTITUTE(LEFT(A6,FIND("@",A6)-1),".","")& MID(A6,FIND("@",A6),LEN(A6)) -> markparker@yahoo.com

Sheet Loan Disbursement Analysis
A1: Loan ID | B1: Loan Type | C1: Loan Amount
A2: 1001 | B2: Personal | C2: 500000
A3: 1002 | B3: Business | C3: 1200000
A4: 1003 | B4: Personal | C4: 700000
A5: 1004 | B5: Business | C5: 2000000
A6: 1005 | B6: Education | C6: 300000
A7: 1006 | B7: Personal | C7: 450000
A8: 1007 | B8: Business | C8: 1500000
A9: 1008 | B9: Education | C9: 200000
A10: 1009 | B10: Personal | C10: 600000
A11: 1010 | B11: Business | C11: 1800000
A12: 1011 | B12: Education | C12: 400000
A13: 1012 | B13: Personal | C13: 550000
... A16: 1015 | B16: Business | C16: 1900000
A18: Total Amount Disbursed for Personal Loans | E18: =SUMIF(B2:B16,"Personal",C2:C16) -> 3550000
A19: Total Amount Disbursed for Business Loans | E19: =SUMIF(B2:B16,"Personal",C2:C16) -> 3550000
A20: Total Amount Disbursed for Education Loans | E20: =SUMIF(B2:B16,"Education",C2:C16) -> 900000

Sheet Branch Allocation
A1: Number | B1: Account Age(Months) | C1: Branch Allocation
A2: 1234567890 | B2: 8 | C2: =MOD(B2,3)+1 -> 3
A3: 9876543210 | B3: 22 | C3: =MOD(B3,3)+1 -> 2
A4: 123456789 | B4: 36 | C4: =MOD(B4,3)+1 -> 1

Sheet Analyzing Monthly Sales
A1: Sale Id | B1: Sale Date | C1: Sale Amount | D1: Month
A2: 1 | B2: 44927 | C2: 50000 | D2: =MONTH(B2) -> 1
A3: 2 | B3: 44941 | C3: 75000 | D3: =MONTH(B3) -> 1
A4: 3 | B4: 44959 | C4: 60000 | D4: =MONTH(B4) -> 2
A5: 4 | B5: 44975 | C5: 85000 | D5: =MONTH(B5) -> 2
A6: 5 | B6: 44990 | C6: 40000 | D6: =MONTH(B6) -> 3
A7: 6 | B7: 45006 | C7: 95000 | D7: =MONTH(B7) -> 3

Sheet Assessing Sales and Advertising
A1: Month | B1: Advertising Spend (INR lakhs) | C1: Sales Revenue(INR Crores)
A2: January | B2: 50 | C2: 1.2
A3: February | B3: 55 | C3: 1.4
A4: March | B4: 60 | C4: 1.5
A5: April | B5: 65 | C5: 1.6
A6: May | B6: 70 | C6: 1.8
A7: June | B7: 75 | C7: 1.9
A8: July | B8: 80 | C8: 2
A9: August | B9: 85 | C9: 2.2
A10: September | B10: 90 | C10: 2.3
A11: October | B11: 95 | C11: 2.5
A12: November | B12: 100 | C12: 2.6
A13: December | B13: 105 | C13: 2.8
A15: Covariance | B15: =+COVAR(B2:B13,C2:C13) -> 8.375
A16: Correlation | B16: =CORREL(B2:B13,C2:C13) -> 0.99798471

Sheet Analyzing Median Delivery Time 
A1: Transaction ID | B1: Delivery Time (Days)
A2: T001 | B2: 3
A3: T002 | B3: 5
A4: T003 | B4: 2
A5: T004 | B5: 4
A6: T005 | B6: 6
A7: T006 | B7: 7
A8: T007 | B8: 5
A9: T008 | B9: 3
A10: T009 | B10: 4
A11: T010 | B11: 2
A14: Median | B14: =MEDIAN(B2:B11) -> 4
A15: Average | B15: =AVERAGE(B2:B11) -> 4.1

Sheet Calculating Total Cost and Disc
A1: Item | B1: Qty | C1: Unit Price | D1: Total Cost | E1: Discount Applied | F1: Final Cost
A2: Sofa Set | B2: 1 | C2: 30000 | D2: =B2*C2 -> 30000 | E2: =0.07*D2 -> 2100 | F2: =D2-E2 -> 27900
A3: Dinning Table | B3: 2 | C3: 15000 | D3: =B3*C3 -> 30000 | E3: =0.07*D3 -> 2100 | F3: =D3-E3 -> 27900
A4: Bed Frame | B4: 1 | C4: 25000 | D4: =B4*C4 -> 25000 | E4: =0.05*D4 -> 1250 | F4: =D4-E4 -> 23750

Sheet Analyzing Student Performance 
A1: Student Id | B1: Grade | C1: Test Score
A2: VED101 | B2: 6th | C2: 85
A3: VED102 | B3: 7th | C3: 78
A4: VED103 | B4: 6th | C4: 92
A5: VED104 | B5: 7th | C5: 69
A6: VED105 | B6: 7th | C6: 87
A8: Grade | B8: Average Score
A9: 6th | B9: =IF(A9="6th",AVERAGE(C2:C6),) -> 82.2
A10: 7th | B10: =IF(A10="7th",AVERAGE(C2:C7),) -> 82.2

Sheet Tracking Monthly Revenue
A1: Month | B1: Mumbai | C1: Delhi | D1: Bengaluru | E1: Hyderabad | F1: Chennai
A2: January | B2: 50000 | C2: 45000 | D2: 40000 | E2: 35000 | F2: 30000
A3: February | B3: 52000 | C3: 47000 | D3: 42000 | E3: 37000 | F3: 32000
A4: March | B4: 53000 | C4: 48000 | D4: 43000 | E4: 38000 | F4: 33000
A5: April | B5: 54000 | C5: 49000 | D5: 44000 | E5: 39000 | F5: 34000
A6: May | B6: 55000 | C6: 50000 | D6: 45000 | E6: 40000 | F6: 35000
A7: June | B7: 56000 | C7: 51000 | D7: 46000 | E7: 41000 | F7: 36000
A9: Data for | B9: Mumbai | C9: for | D9: March | E9: =VLOOKUP(D9,A1:F7,2) -> 53000 | F9: =VLOOKUP(B9,A1:F7,MATCH(D9,A2:A7,0),FALSE) -> #N/A
A10: Data for | B10: Bengaluru | C10: for | D10: April | E10: =VLOOKUP(D10,A1:F7,2) -> #N/A

Sheet Tracking Delivery Times
A1: Order Id | B1: Order Date & time | C1: Delivery Date & time | D1: Time taken(In hours)
A2: 1 | B2: 45572.417 | C2: 45572.521 | D2: =(C2-B2)*24 -> 2.5
A3: 2 | B3: 45572.479 | C3: 45572.583 | D3: =(C3-B3)*24 -> 2.5
A4: 3 | B4: 45572.542 | C4: 45572.656 | D4: =(C4-B4)*24 -> 2.75
A5: 4 | B5: 45572.625 | C5: 45572.719 | D5: =(C5-B5)*24 -> 2.25
A6: 5 | B6: 45572.729 | C6: 45572.781 | D6: =(C6-B6)*24 -> 1.25
A8: Average Delivery Time | B8: =AVERAGE(D2:D6) -> 2.25
A9: Date and time of last delivery | B9: =LARGE(C2:C6,1) -> 45572.781

Sheet Encoding Course Categories
A1: Course Category | B1: ASCII Code | C1: Character
A2: UPSC | B2: 85 | C2: =CHAR(B2) -> U
A3: NEET | B3: 78 | C3: =CHAR(B3) -> N
A4: JEE | B4: 74 | C4: =CHAR(B4) -> J
A5: CAT | B5: 67 | C5: =CHAR(B5) -> C
A6: GATE | B6: 71 | C6: =CHAR(B6) -> G

Sheet Calculating Total Revenue 
A1: Month | B1: Revenue in $MM
A2: Janaury | B2: 820
A3: February | B3: 215
A4: March | B4: 60
A5: April | B5: 470
A6: May | B6: 210
A7: June | B7: 75
A8: July | B8: 750
A9: August | B9: 490
A10: September | B10: 630
A11: October | B11: 260
A12: November | B12: 720
A13: December | B13: 210
A15: Total Year | B15: =SUM(B2:B13) -> 4910

Sheet Rounding Down Monthly
A1: Product | B1: Monthly Revenue | C1: Rounded Down Monthly Revenue
A2: Freshdesk | B2: 15432 | C2: =ROUNDDOWN(B2,-3) -> 15000
A3: Freshservice | B3: 29756 | C3: =ROUNDDOWN(B3,-3) -> 29000
A4: Freshsales | B4: 8345 | C4: =ROUNDDOWN(B4,-3) -> 8000
A5: Freshmarketer | B5: 45321 | C5: =ROUNDDOWN(B5,-3) -> 45000
A6: Freshteam | B6: 12367 | C6: =ROUNDDOWN(B6,-3) -> 12000
A7: Freshchat | B7: 23154 | C7: =ROUNDDOWN(B7,-3) -> 23000
A8: Freshcaller | B8: 18732 | C8: =ROUNDDOWN(B8,-3) -> 18000
A9: Freshping | B9: 6543 | C9: =ROUNDDOWN(B9,-3) -> 6000
A10: Freshstatus | B10: 34987 | C10: =ROUNDDOWN(B10,-3) -> 34000
A11: Freshrelease | B11: 9812 | C11: =ROUNDDOWN(B11,-3) -> 9000

Sheet Analyzing Volunteer Engagement
A1: Region | B1: Volunteering Hours
A2: North | B2: 15
A3: North | B3: 20
A4: North | B4: 18
A5: North | B5: 22
A6: South | B6: 25
A7: South | B7: 30
A8: South | B8: 28
A9: South | B9: 32
A10: East | B10: 10
A11: East | B11: 12
A12: East | B12: 14
A13: East | B13: 16
... A17: West | B17: 26
A19: Answer | B19: =_xlfn.STDEV.P(B2:B17) -> 6.2537489

Sheet Vehicle Age Classification
A1: Vehicle ID | B1: Vehicle Model | C1: Manufacturing Year | D1: Age Classification
A2: 1001 | B2: Maruti Swift | C2: 2023 | D2: =IF(C2>=2022,"New", IF(AND(C2>=2018,C2<=2021),"Moderate", IF(AND(C2>=2015,C2<=2017),"Old", IF(C2<=2014,"Very Old","") ))) -> New
A3: 1002 | B3: Hyundai i20 | C3: 2020 | D3: =IF(C3>=2022,"New", IF(AND(C3>=2018,C3<=2021),"Moderate", IF(AND(C3>=2015,C3<=2017),"Old", IF(C3<=2014,"Very Old","") ))) -> Moderate
A4: 1003 | B4: Honda City | C4: 2017 | D4: =IF(C4>=2022,"New", IF(AND(C4>=2018,C4<=2021),"Moderate", IF(AND(C4>=2015,C4<=2017),"Old", IF(C4<=2014,"Very Old","") ))) -> Old
A5: 1004 | B5: Toyota Fortuner | C5: 2015 | D5: =IF(C5>=2022,"New", IF(AND(C5>=2018,C5<=2021),"Moderate", IF(AND(C5>=2015,C5<=2017),"Old", IF(C5<=2014,"Very Old","") ))) -> Old
A6: 1005 | B6: Tata Nexon | C6: 2019 | D6: =IF(C6>=2022,"New", IF(AND(C6>=2018,C6<=2021),"Moderate", IF(AND(C6>=2015,C6<=2017),"Old", IF(C6<=2014,"Very Old","") ))) -> Moderate
A7: 1006 | B7: Ford EcoSport | C7: 2014 | D7: =IF(C7>=2022,"New", IF(AND(C7>=2018,C7<=2021),"Moderate", IF(AND(C7>=2015,C7<=2017),"Old", IF(C7<=2014,"Very Old","") ))) -> Very Old
A8: 1007 | B8: Kia Seltos | C8: 2022 | D8: =IF(C8>=2022,"New", IF(AND(C8>=2018,C8<=2021),"Moderate", IF(AND(C8>=2015,C8<=2017),"Old", IF(C8<=2014,"Very Old","") ))) -> New
A9: 1008 | B9: Mahindra Scorpio | C9: 2016 | D9: =IF(C9>=2022,"New", IF(AND(C9>=2018,C9<=2021),"Moderate", IF(AND(C9>=2015,C9<=2017),"Old", IF(C9<=2014,"Very Old","") ))) -> Old
A10: 1009 | B10: Volkswagen Polo | C10: 2013 | D10: =IF(C10>=2022,"New", IF(AND(C10>=2018,C10<=2021),"Moderate", IF(AND(C10>=2015,C10<=2017),"Old", IF(C10<=2014,"Very Old","") ))) -> Very Old
A11: 1010 | B11: Renault Kwid | C11: 2021 | D11: =IF(C11>=2022,"New", IF(AND(C11>=2018,C11<=2021),"Moderate", IF(AND(C11>=2015,C11<=2017),"Old", IF(C11<=2014,"Very Old","") ))) -> Moderate

Sheet Advanced Inventory Analysis
A1: Product Id | B1: Product Name | C1: Category | D1: Stock Quantity | E1: Price per Unit | F1: Supplier
A2: 101 | B2: Basmati Rice | C2: Grains | D2: 150 | E2: 60 | F2: Supplier A
A3: 102 | B3: Wheat flour | C3: Grains | D3: 200 | E3: 40 | F3: Supplier B
A4: 103 | B4: Turmeric Powder | C4: Spices | D4: 80 | E4: 120 | F4: Supplier A
A5: 104 | B5: Red Chilli Powder | C5: Spices | D5: 100 | E5: 150 | F5: Supplier C
A6: 105 | B6: Sunflower oil | C6: Oils | D6: 50 | E6: 130 | F6: Supplier B
A7: 106 | B7: Mustard Oil | C7: Oils | D7: 75 | E7: 110 | F7: Supplier A
A8: 107 | B8: Sugar | C8: Sweetners | D8: 250 | E8: 45 | F8: Supplier C
A9: 108 | B9: Salt | C9: Condiments | D9: 300 | E9: 20 | F9: Supplier B
A10: 109 | B10: Honey | C10: Sweetners | D10: 60 | E10: 180 | F10: Supplier A
A11: 110 | B11: Green Tea | C11: Beverages | D11: 90 | E11: 250 | F11: Supplier C
B14: Stock Quantity of: | C14: Mustard Oil | D14: =VLOOKUP(C14,B1:F11,3,FALSE) -> 75
B15: Total Value of Stock for | C15: Supplier A | D15: =SUMPRODUCT((F2:F11=C15)*D2:D11*E2:E11) -> 37650
C16: Supplier B | D16: =SUMPRODUCT((F2:F11=C16)*D2:D11*E2:E11) -> 20500
C17: Supplier C | D17: =SUMPRODUCT((F2:F11=C17)*D2:D11*E2:E11) -> 48750

Sheet Lead Conversion Calculator
A1: Campaign | B1: January | C1: February | D1: March | E1: April | F1: May | G1: June
A2: Campaign A | B2: 0.05 | C2: 0.07 | D2: 0.06 | E2: 0.08 | F2: 0.075 | G2: 0.09
A3: Campaign B | B3: 0.045 | C3: 0.06 | D3: 0.07 | E3: 0.085 | F3: 0.068 | G3: 0.1
A4: Campaign C | B4: 0.06 | C4: 0.072 | D4: 0.065 | E4: 0.09 | F4: 0.083 | G4: 0.095
A5: Campaign D | B5: 0.055 | C5: 0.065 | D5: 0.073 | E5: 0.088 | F5: 0.077 | G5: 0.102
A8: Conversion Rate Calculator | D8: Campaign A | E8: March | F8: =VLOOKUP(D8,A1:G5,4) -> 0.06
D9: Campaign B | E9: April | F9: =VLOOKUP(D9,A1:G5,3) -> 0.06
D10: Campaign C | E10: May | F10: =VLOOKUP(D10,A1:G5,6) -> 0.083
D11: Campaign A | E11: January | F11: =VLOOKUP(D11,A1:G5,2) -> 0.05
D12: Campaign B | E12: February | F12: =VLOOKUP(D12,A1:G5,3) -> 0.06

Sheet Average Mango Prices
A1: State | B1: Price per kg
A2: Maharashtra | B2: 85
A3: Andhra Pradesh | B3: 72
A4: Karnataka | B4: 90
A5: Gujarat | B5: 80
A7: Answer | B7: =AVERAGE(B2:B5) -> 81.75

Sheet Analyzing Customer Support Tkt
A1: Ticket id | B1: Raw Ticket Data | C1: Customer Full Name | D1: Ticket Number | E1: Issue Description
A2: T001 | B2: John,Doe[#12345]-Internet is down since last night | C2: =SUBSTITUTE(LEFT(B2,FIND("[#",B2)-1),","," ") -> John Doe | D2: =MID(B2,FIND("[#",B2)+2,FIND("]",B2)-FIND("[#",B2)-2) -> 12345 | E2: =MID(B2, FIND("]-", B2) + 2, LEN(B2)) -> Internet is down since last night | F2: =FIND("-", B2) -> 17
A3: T002 | B3: Mary,Jane[#23456]-Billing Issue: charged twice for the same month | C3: =SUBSTITUTE(LEFT(B3,FIND("[#",B3)-1),","," ") -> Mary Jane | D3: =MID(B3,FIND("[#",B3)+2,FIND("]",B3)-FIND("[#",B3)-2) -> 23456 | E3: =MID(B3,FIND("]-",B3)+2,LEN(B3)) -> Billing Issue: charged twice for the same month
A4: T003 | B4: Ahmed,Khan [#34567]- Need assistance with setting up a new router | C4: =SUBSTITUTE(LEFT(B4,FIND("[#",B4)-1),","," ") -> Ahmed Khan | D4: =MID(B4,FIND("[#",B4)+2,FIND("]",B4)-FIND("[#",B4)-2) -> 34567 | E4: =MID(B4,FIND("]-",B4)+2,LEN(B4)) -> Need assistance with setting up a new router
A5: T004 | B5: Priya, Sharma [#45678]-The network coverage is poor in my area | C5: =SUBSTITUTE(LEFT(B5,FIND("[#",B5)-1),","," ") -> Priya Sharma | D5: =MID(B5,FIND("[#",B5)+2,FIND("]",B5)-FIND("[#",B5)-2) -> 45678 | E5: =MID(B5,FIND("]-",B5)+2,LEN(B5)) -> The network coverage is poor in my area
A6: T005 | B6: Rajesh,Gupta [#56789]- Connection speed is very slow,experiencing frequent disconnections | C6: =SUBSTITUTE(LEFT(B6,FIND("[#",B6)-1),","," ") -> Rajesh Gupta | D6: =MID(B6,FIND("[#",B6)+2,FIND("]",B6)-FIND("[#",B6)-2) -> 56789 | E6: =MID(B6,FIND("]-",B6)+2,LEN(B6)) -> Connection speed is very slow,experiencing frequent disconnections

Sheet Customer Loan Details Analysis
A1: Customer Id | B1: Raw Loan Data | C1: Customer Name | D1: Loan Amount | E1: Interest Rate | F1: Tenure | G1: Status | H1: Total Interest | I1: Approval Status | J1: Approved and Above Avg
A2: C001 | B2: ramesh kumar,Loan Amount:500000,Interest Rate:7.5%Tenure:10 Years,Approved | C2: =PROPER(LEFT(B2, FIND(",", B2)-1)) -> Ramesh Kumar | D2: =MID(B2, FIND("Loan Amount:", B2)+12, FIND(",", B2, FIND("Loan Amount:", B2)) - (FIND("Loan Amount:", B2)+12)) -> 500000 | E2: =VALUE(SUBSTITUTE(MID(B2, FIND("Interest Rate:",B2)+14, FIND("Tenure:",B2)- (FIND("Interest Rate:",B2)+14)),"%","")) -> 7.5 | F2: =MID(B2, FIND("Tenure:",B2)+7, FIND(",",B2,FIND("Tenure:",B2))- (FIND("Tenure:",B2)+12)) -> 10 | H2: =D2*E2*F2/100 -> 375000
A3: C002 | B3: Rita Gupta,Loan Amount:300000,Interest Rate:8.2%Tenure:7 Years,Rejected | C3: =PROPER(LEFT(B3,FIND(",",B3)-1)) -> Rita Gupta | D3: =MID(B3, FIND("Loan Amount:", B3)+12, FIND(",", B3, FIND("Loan Amount:", B3)) - (FIND("Loan Amount:", B3)+12)) -> 300000 | E3: =VALUE(SUBSTITUTE(MID(B3, FIND("Interest Rate:",B3)+14, FIND("Tenure:",B3)- (FIND("Interest Rate:",B3)+14)),"%","")) -> 8.2 | F3: =MID(B3, FIND("Tenure:",B3)+7, FIND(",",B3,FIND("Tenure:",B3))- (FIND("Tenure:",B3)+12)) -> 7 | H3: =D3*E3*F3/100 -> 172200
A4: C003 | B4: Vijay singh,Loan Amount:1000000,Interest Rate:6.9%Tenure:15 Years,Approved | C4: =PROPER(LEFT(B4,FIND(",",B4)-1)) -> Vijay Singh | D4: =MID(B4, FIND("Loan Amount:", B4)+12, FIND(",", B4, FIND("Loan Amount:", B4)) - (FIND("Loan Amount:", B4)+12)) -> 1000000 | E4: =VALUE(SUBSTITUTE(MID(B4, FIND("Interest Rate:",B4)+14, FIND("Tenure:",B4)- (FIND("Interest Rate:",B4)+14)),"%","")) -> 6.9 | F4: =MID(B4, FIND("Tenure:",B4)+7, FIND(",",B4,FIND("Tenure:",B4))- (FIND("Tenure:",B4)+12)) -> 15 | H4: =D4*E4*F4/100 -> 1035000
A5: C004 | B5: priya Iyer,Loan Amount:250000,Interest Rate:7.8%Tenure:5 Years,Approved | C5: =PROPER(LEFT(B5,FIND(",",B5)-1)) -> Priya Iyer | D5: =MID(B5, FIND("Loan Amount:", B5)+12, FIND(",", B5, FIND("Loan Amount:", B5)) - (FIND("Loan Amount:", B5)+12)) -> 250000 | E5: =VALUE(SUBSTITUTE(MID(B5, FIND("Interest Rate:",B5)+14, FIND("Tenure:",B5)- (FIND("Interest Rate:",B5)+14)),"%","")) -> 7.8 | F5: =MID(B5, FIND("Tenure:",B5)+7, FIND(",",B5,FIND("Tenure:",B5))- (FIND("Tenure:",B5)+12)) -> 5 | H5: =D5*E5*F5/100 -> 97500
A6: C005 | B6: Anil Kumar,Loan Amount:750000,Interest Rate:8.0%Tenure:12 Years,Approved | C6: =PROPER(LEFT(B6,FIND(",",B6)-1)) -> Anil Kumar | D6: =MID(B6, FIND("Loan Amount:", B6)+12, FIND(",", B6, FIND("Loan Amount:", B6)) - (FIND("Loan Amount:", B6)+12)) -> 750000 | E6: =VALUE(SUBSTITUTE(MID(B6, FIND("Interest Rate:",B6)+14, FIND("Tenure:",B6)- (FIND("Interest Rate:",B6)+14)),"%","")) -> 8 | F6: =MID(B6, FIND("Tenure:",B6)+7, FIND(",",B6,FIND("Tenure:",B6))- (FIND("Tenure:",B6)+12)) -> 12 | H6: =D6*E6*F6/100 -> 720000

Sheet Targeting Mobile App Users
A1: User Id | B1: City Tier | C1: Average Daily App Usage (In Minutes) | D1: Meets Condition
A2: USR123 | B2: Tier 1 | C2: 45 | D2: =IF(AND(B2="Tier 1",C2>30),TRUE,FALSE) -> TRUE
A3: USR456 | B3: Tier 2 | C3: 20 | D3: =IF(AND(B3="Tier 1",C3>30),TRUE,FALSE) -> FALSE
A4: USR789 | B4: Tier 1 | C4: 10 | D4: =IF(AND(B4="Tier 1",C4>30),TRUE,FALSE) -> FALSE
A5: USR012 | B5: Tier 3 | C5: 60 | D5: =IF(AND(B5="Tier 1",C5>30),TRUE,FALSE) -> FALSE

Sheet Standardizing Seller
A1: Seller Id | B1: Seller Name | C1: Joining Month | D1: Standardizing Seller Name | E1: Standardizing Month Name
A2: 101 | B2: Ram Trdaing Co. | C2: January | D2: =LOWER(B2) -> ram trdaing co. | E2: =LOWER(C2) -> january
A3: 102 | B3: MAHESH Enterprises | C3: February | D3: =LOWER(B3) -> mahesh enterprises | E3: =LOWER(C3) -> february
A4: 103 | B4: Vinayaka STORES | C4: March | D4: =LOWER(B4) -> vinayaka stores | E4: =LOWER(C4) -> march
A5: 104 | B5: Anand & Sons | C5: April | D5: =LOWER(B5) -> anand & sons | E5: =LOWER(C5) -> april
A6: 105 | B6: SHREE GANESH Mart | C6: May | D6: =LOWER(B6) -> shree ganesh mart | E6: =LOWER(C6) -> may

Sheet Optimizing Delivery Capacity 
A1: Area | B1: Friday Evening | C1: Saturday Daytime | D1: Saturday Eveninh | E1: Sunday Daytime | F1: Sunday Evening | G1: Highest Ride Request
A2: South Mumbai | B2: 250 | C2: 180 | D2: 320 | E2: 150 | F2: 200 | G2: =LARGE(B2:F2,1) -> 320
A3: Bandra-Kurla Complex | B3: 120 | C3: 210 | D3: 180 | E3: 140 | F3: 160 | G3: =LARGE(B3:F3,1) -> 210
A4: Andheri West | B4: 300 | C4: 250 | D4: 350 | E4: 220 | F4: 280 | G4: =LARGE(B4:F4,1) -> 350
A5: Powai | B5: 180 | C5: 150 | D5: 200 | E5: 120 | F5: 130 | G5: =LARGE(B5:F5,1) -> 200

Sheet Analyzing Ad Engagement
A1: Ad ID | B1: Ad Type | C1: Impressions | D1: Clicks | E1: Has Zero Clicks
A2: A001 | B2: Banner Ad | C2: 5000 | D2: 120 | E2: =IF(D2=0,TRUE,FALSE) -> FALSE
A3: A002 | B3: Video Ad | C3: 3000 | D3: 0 | E3: =IF(D3=0,TRUE,FALSE) -> TRUE
A4: A003 | B4: Carousel Ad | C4: 4500 | D4: 80 | E4: =IF(D4=0,TRUE,FALSE) -> FALSE
A5: A004 | B5: Sponsored Post | C5: 6000 | D5: 150 | E5: =IF(D5=0,TRUE,FALSE) -> FALSE
A6: A005 | B6: Display Ad | C6: 2500 | D6: 0 | E6: =IF(D6=0,TRUE,FALSE) -> TRUE
A7: A006 | B7: Native Ad | C7: 4000 | D7: 60 | E7: =IF(D7=0,TRUE,FALSE) -> FALSE
A8: A007 | B8: Text Ad | C8: 3500 | D8: 90 | E8: =IF(D8=0,TRUE,FALSE) -> FALSE
A9: A008 | B9: Pop-up Ad | C9: 2000 | D9: 0 | E9: =IF(D9=0,TRUE,FALSE) -> TRUE
A10: A009 | B10: Overlay Ad | C10: 2800 | D10: 70 | E10: =IF(D10=0,TRUE,FALSE) -> FALSE
A11: A010 | B11: Interactive Ad | C11: 5000 | D11: 110 | E11: =IF(D11=0,TRUE,FALSE) -> FALSE
A13: Answer | B13: =COUNTIF(E2:E11,TRUE) -> 3

Sheet Matching Customer Engagement
A1: Service Name | B1: Engagement Rate (%)
A2: SMS Marketing | B2: 45
A3: Chatbots | B3: 62
A4: Voice Messaging | B4: 53
A5: Email Integration | B5: 37
A6: Push Notifications | B6: 58
A8: Chatbots | B8: =VLOOKUP(A8,A1:B6,2,FALSE) -> 62

Sheet Analyzing Cricket Contest Data
A1: Month | B1: Contest A | C1: Contest B | D1: Contest C | E1: Contest D | F1: Contest E
A2: January | B2: 150000 | C2: 200000 | D2: 175000 | E2: 220000 | F2: 180000
A3: February | B3: 160000 | C3: 210000 | D3: 185000 | E3: 230000 | F3: 190000
A4: March | B4: 170000 | C4: 220000 | D4: 195000 | E4: 240000 | F4: 200000
A5: April | B5: 180000 | C5: 230000 | D5: 205000 | E5: 250000 | F5: 210000
A6: May | B6: 190000 | C6: 240000 | D6: 215000 | E6: 260000 | F6: 220000
A7: June | B7: 200000 | C7: 250000 | D7: 225000 | E7: 270000 | F7: 230000
A9: Contest Name | B9: Target Month | C9: Prize Money
A10: Contest B | B10: March | C10: =VLOOKUP(B10,A1:F7,3,FALSE) -> 220000
A11: Contest C | B11: February | C11: =VLOOKUP(B11,A1:F7,4,FALSE) -> 185000
A12: Contest E | B12: June | C12: =VLOOKUP(B12,A2:F7,6,FALSE) -> 230000

Sheet Daily Cash Deposit Analysis
A1: Day | B1: Total Cash Deposited
A2: Monday | B2: 254872
A3: Tuesday | B3: 189541
A4: Wednesday | B4: 321457
A5: Thursday | B5: 217890
A6: Friday | B6: 482569
A7: Saturday | B7: 314872
A8: Sunday | B8: 152489
A10: Answer | B10: =COUNTIF(B2:B8, ">=" & AVERAGE(B2:B8)) -> 3
B11: =COUNTIF(B2:B8,"<" & AVERAGE(B2:B8)) -> 4

Sheet Ranking Car Models
A1: Car Model | B1: Units Sold Q1 2024 | C1: Rank
A2: Maruti Swift | B2: 150 | C2: =RANK($B$2:$B$6,$B$2:$B$6,0) -> 1
A3: Tata Nexon | B3: 90 | C3: =RANK($B$2:$B$6,$B$2:$B$6,0) -> 3
A4: Hyundai i20 | B4: 120 | C4: =RANK($B$2:$B$6,$B$2:$B$6,0) -> 2
A5: Mahindra XUV500 | B5: 70 | C5: =RANK($B$2:$B$6,$B$2:$B$6,0) -> 5
A6: Honda City | B6: 80 | C6: =RANK($B$2:$B$6,$B$2:$B$6,0) -> 4

Sheet Booking Analysis for Oberoi
A1: Booking ID | B1: Customer Name | C1: Check In Date | D1: Check Out Date | E1: Year | F1: Stay Duration
A2: 1 | B2: John Doe | C2: 44923 | D2: 44928 | E2: =YEAR(C2) -> 2022 | F2: =_xlfn.DAYS(D2,C2) -> 5
A3: 2 | B3: Jane Smith | C3: 45000 | D3: 45003 | E3: =YEAR(C3) -> 2023 | F3: =_xlfn.DAYS(D3,C3) -> 3
A4: 3 | B4: Miachel Brown | C4: 45066 | D4: 45071 | E4: =YEAR(C4) -> 2023 | F4: =_xlfn.DAYS(D4,C4) -> 5
A5: 4 | B5: Sarah Johnson | C5: 45117 | D5: 45122 | E5: =YEAR(C5) -> 2023 | F5: =_xlfn.DAYS(D5,C5) -> 5
A6: 5 | B6: David Lee | C6: 45174 | D6: 45179 | E6: =YEAR(C6) -> 2023 | F6: =_xlfn.DAYS(D6,C6) -> 5
A7: 6 | B7: Emily Wang | C7: 45242 | D7: 45245 | E7: =YEAR(C7) -> 2023 | F7: =_xlfn.DAYS(D7,C7) -> 3
A8: 7 | B8: Chris Chen | C8: 45299 | D8: 45303 | E8: =YEAR(C8) -> 2024 | F8: =_xlfn.DAYS(D8,C8) -> 4
A11: How Many Bookings were made in 2023? | B11: =COUNTIFS(C2:C8,">=01/01/2023",C2:C8,"<=31/12/2023") -> 5
A12: What is the average length of stay (in days) for these bookings | B12: =AVERAGE(F2:F8) -> 4.2857143

Sheet Extracting Last Digits of VRN
A1: Vehicle Registeration Number | B1: Vehicle Type | C1: Manufacturing Year | D1: Registeration State | E1: Last Digits of Registeration
A2: DL3CA1234 | B2: Hatchback | C2: 2018 | D2: Delhi | E2: =RIGHT(A2,4) -> 1234
A3: MH12AB5678 | B3: Sedan | C3: 2019 | D3: Maharashtra | E3: =RIGHT(A3,4) -> 5678
A4: KA01CD9876 | B4: SUV | C4: 2020 | D4: Karnataka | E4: =RIGHT(A4,4) -> 9876
A5: GJ05EF2345 | B5: Hatchback | C5: 2017 | D5: Gujarat | E5: =RIGHT(A5,4) -> 2345
A6: TN07GH8765 | B6: Sedan | C6: 2016 | D6: Tamil Nadu | E6: =RIGHT(A6,4) -> 8765
A7: HR02IJ3456 | B7: SUV | C7: 2021 | D7: Haryana | E7: =RIGHT(A7,4) -> 3456
A8: RJ03KL6789 | B8: Hatchback | C8: 2015 | D8: Rajasthan | E8: =RIGHT(A8,4) -> 6789
A9: UP04MN4321 | B9: Sedan | C9: 2014 | D9: Uttar Pradesh | E9: =RIGHT(A9,4) -> 4321
A10: PB05OP1234 | B10: SUV | C10: 2013 | D10: Punjab | E10: =RIGHT(A10,4) -> 1234
A11: MP06QR7890 | B11: Hatchback | C11: 2012 | D11: Madhya Pradesh | E11: =RIGHT(A11,4) -> 7890

Sheet Managing API Deployment
A1: Project ID | B1: Start Date | C1: Estimated Completion (days) | D1: Planned Deployment Dates | E1: Current Progress
A2: P001 | B2: 46039 | C2: 30 | D2: =B2+C2 -> 46069 | E2: =IF(TODAY()>D2,"Deployed","In Progress") -> Deployed
A3: P002 | B3: 46034 | C3: 45 | D3: =B3+C3 -> 46079 | E3: =IF(TODAY()>D3,"Deployed","In Progress") -> Deployed
A4: P003 | B4: 46024 | C4: 60 | D4: =B4+C4 -> 46084 | E4: =IF(TODAY()>D4,"Deployed","In Progress") -> Deployed
A5: P004 | B5: 46054 | C5: 90 | D5: =B5+C5 -> 46144 | E5: =IF(TODAY()>D5,"Deployed","In Progress") -> In Progress
A6: P005 | B6: 45884 | C6: 120 | D6: =B6+C6 -> 46004 | E6: =IF(TODAY()>D6,"Deployed","In Progress") -> Deployed

Sheet Managing Loan Repayment Dates
A1: Loan Id | B1: Loan Issue Date | C1: Repayment Term (Months) | D1: Loan Due Dates | E1: Overdue Status
A2: 1 | B2: 45724 | C2: 3 | D2: =B2+DATE(,C2,) -> 45784 | E2: =IF(D2<TODAY(),"Overdue","On time") -> Overdue
A3: 2 | B3: 46083 | C3: 2 | D3: =B3+DATE(,C3,) -> 46114 | E3: =IF(D3<TODAY(),"Overdue","On time") -> On time
A4: 3 | B4: 46082 | C4: 4 | D4: =B4+DATE(,C4,) -> 46173 | E4: =IF(D4<TODAY(),"Overdue","On time") -> On time
A5: 4 | B5: 45728 | C5: 1 | D5: =B5+DATE(,C5,) -> 45728 | E5: =IF(D5<TODAY(),"Overdue","On time") -> Overdue
A6: 5 | B6: 45725 | C6: 3 | D6: =B6+DATE(,C6,) -> 45785 | E6: =IF(D6<TODAY(),"Overdue","On time") -> Overdue

Sheet Formatting Customer Names 
A1: Customer Id | B1: Customer Name | C1: Proper Case Name
A2: 101 | B2: john doe | C2: =PROPER(B2) -> John Doe
A3: 102 | B3: JANE SMITH | C3: =PROPER(B3) -> Jane Smith
A4: 103 | B4: rahul kumar | C4: =PROPER(B4) -> Rahul Kumar
A5: 104 | B5: SONALI ROY | C5: =PROPER(B5) -> Sonali Roy
A6: 105 | B6: kapil dev | C6: =PROPER(B6) -> Kapil Dev

Sheet Analyzing Property Listing Ages
A1: Property Id | B1: City | C1: Property Type | D1: Listing Date | E1: Age of Property Listings (In Days)
A2: P001 | B2: Bangalore | C2: Apartment | D2: 45092 | E2: =_xlfn.DAYS(TODAY(),D2) -> 1017
A3: P002 | B3: Mumbai | C3: Villa | D3: 45108 | E3: =_xlfn.DAYS(TODAY(),D3) -> 1001
A4: P003 | B4: Delhi | C4: House | D4: 45117 | E4: =_xlfn.DAYS(TODAY(),D4) -> 992
A5: P004 | B5: Hyderabad | C5: Apartment | D5: 45127 | E5: =_xlfn.DAYS(TODAY(),D5) -> 982
A6: P005 | B6: Pune | C6: Apartment | D6: 45143 | E6: =_xlfn.DAYS(TODAY(),D6) -> 966
A7: P006 | B7: Chennai | C7: Villa | D7: 45153 | E7: =_xlfn.DAYS(TODAY(),D7) -> 956
A8: P007 | B8: Kolkata | C8: House | D8: 45170 | E8: =_xlfn.DAYS(TODAY(),D8) -> 939
A9: P008 | B9: Ahmedabad | C9: Apartment | D9: 45719 | E9: =_xlfn.DAYS(TODAY(),D9) -> 390
A10: P009 | B10: Gurugram | C10: Apartment | D10: 46054 | E10: =_xlfn.DAYS(TODAY(),D10) -> 55
A11: P010 | B11: Jaipur | C11: House | D11: 46084 | E11: =_xlfn.DAYS(TODAY(),D11) -> 25
B15: Average Age of Properties by City | E15: Bangalore | F15: =AVERAGEIF(B2:B11,"Bangalore",E2:E11) -> 1017

Sheet Advanced Portfolio Analysis
A1: Client Id | B1: Client Name | C1: Stock Symbol | D1: Quantity | E1: Purchase Price | F1: Current Price | G1: Portfolio Value
A2: 1 | B2: Rajesh Kumar | C2: TCS | D2: 50 | E2: 3000 | F2: 3200 | G2: 160000
A3: 2 | B3: Anjali Sharma | C3: INFY | D3: 100 | E3: 1500 | F3: 1400 | G3: 140000
A4: 3 | B4: Vivek Gupta | C4: RELIANCE | D4: 200 | E4: 2000 | F4: 2100 | G4: 420000
A5: 4 | B5: Sneha Patel | C5: HDFC | D5: 150 | E5: 1800 | F5: 1900 | G5: 285000
A6: 5 | B6: Amit Rao | C6: ICICIBANK | D6: 80 | E6: 400 | F6: 420 | G6: 33600
A7: 6 | B7: Priya Mehta | C7: WIPRO | D7: 120 | E7: 500 | F7: 490 | G7: 58800
A8: 7 | B8: Manish Agarwal | C8: SBI | D8: 250 | E8: 350 | F8: 360 | G8: 90000
A9: 8 | B9: Kavita Joshi | C9: HCLTECH | D9: 70 | E9: 900 | F9: 950 | G9: 66500
A10: 9 | B10: Rohan Das | C10: BHARTIAIRTL | D10: 60 | E10: 650 | F10: 700 | G10: 42000
A11: 10 | B11: Neha Verma | C11: AXISBANK | D11: 90 | E11: 700 | F11: 720 | G11: 64800
B13: Row Number of | C13: Vivek Gupta | D13: =MATCH("Vivek Gupta",B2:B11,0) -> 3
B14: Purchase Price of | C14: HDFC | D14: =VLOOKUP(C14,C1:G11,2,FALSE) -> 150
B15: Current Price of | C15: ICICIBANK | D15: =VLOOKUP(C15,C1:G11,4) -> 420

Sheet Calculating Tiered Discounts
A1: Customer Name | B1: Total Purchase Amount | C1: Loyalty Tier | D1: Discount % | E1: Discount Applied | F1: Final Cost
A2: Radha | B2: 8500 | C2: =IF(AND(B2>=10000, B2<20000), "Platinum", IF(AND(B2>=5000, B2<10000), "Gold", IF(AND(B2>=2000, B2<5000), "Silver", IF(B2<2000, "Regular", "Not Suitable")))) -> Gold | D2: =IF(C2="Platinum","15%", IF(C2="Gold","10%", IF(C2="Silver","5%", IF(C2="Regular","No Discount","")))) -> 10% | E2: =D2*B2 -> 850 | F2: =B2-E2 -> 7650
A3: Suresh | B3: 3000 | C3: =IF(AND(B3>=10000, B3<20000), "Platinum", IF(AND(B3>=5000, B3<10000), "Gold", IF(AND(B3>=2000, B3<5000), "Silver", IF(B3<2000, "Regular", "Not Suitable")))) -> Silver | D3: =IF(C3="Platinum","15%", IF(C3="Gold","10%", IF(C3="Silver","5%", IF(C3="Regular","No Discount","")))) -> 5% | E3: =D3*B3 -> 150 | F3: =B3-E3 -> 2850
A4: Priya | B4: 12000 | C4: =IF(AND(B4>=10000, B4<20000), "Platinum", IF(AND(B4>=5000, B4<10000), "Gold", IF(AND(B4>=2000, B4<5000), "Silver", IF(B4<2000, "Regular", "Not Suitable")))) -> Platinum | D4: =IF(C4="Platinum","15%", IF(C4="Gold","10%", IF(C4="Silver","5%", IF(C4="Regular","No Discount","")))) -> 15% | E4: =D4*B4 -> 1800 | F4: =B4-E4 -> 10200

Sheet Analyzing the Relationship
A1: Month | B1: Deliveries | C1: Customer Satisfaction
A2: January | B2: 15000 | C2: 8.2
A3: February | B3: 16000 | C3: 8
A4: March | B4: 17000 | C4: 7.8
A5: April | B5: 18000 | C5: 7.5
A6: May | B6: 19000 | C6: 7.2
A7: June | B7: 20000 | C7: 7
A8: July | B8: 21000 | C8: 6.8
A9: August | B9: 22000 | C9: 6.5
A10: September | B10: 23000 | C10: 6.3
A11: October | B11: 24000 | C11: 6
A12: November | B12: 25000 | C12: 5.8
A13: December | B13: 26000 | C13: 5.5
A15: Correlation Coefficient | B15: =CORREL(B2:B13,C2:C13) -> -0.99930529

Sheet Analyzing Customer Satisfaction
A1: Transaction ID | B1: Customer ranking | C1: Percentile Rank
A2: T001 | B2: 4 | C2: =_xlfn.PERCENTRANK.INC($B$2:$B$11, B2) -> 0.555
A3: T002 | B3: 2 | C3: =_xlfn.PERCENTRANK.INC($B$2:$B$11, B3) -> 0.111
A4: T003 | B4: 5 | C4: =_xlfn.PERCENTRANK.INC($B$2:$B$11, B4) -> 0.888
A5: T004 | B5: 3 | C5: =_xlfn.PERCENTRANK.INC($B$2:$B$11, B5) -> 0.333
A6: T005 | B6: 4 | C6: =_xlfn.PERCENTRANK.INC($B$2:$B$11, B6) -> 0.555
A7: T006 | B7: 1 | C7: =_xlfn.PERCENTRANK.INC($B$2:$B$11, B7) -> 0
A8: T007 | B8: 3 | C8: =_xlfn.PERCENTRANK.INC($B$2:$B$11, B8) -> 0.333
A9: T008 | B9: 2 | C9: =_xlfn.PERCENTRANK.INC($B$2:$B$11, B9) -> 0.111
A10: T009 | B10: 5 | C10: =_xlfn.PERCENTRANK.INC($B$2:$B$11, B10) -> 0.888
A11: T010 | B11: 4 | C11: =_xlfn.PERCENTRANK.INC($B$2:$B$11, B11) -> 0.555

Sheet Analyzing Daily Transaction
A1: Date | B1: Transaction Count | C1: Truncated Amount
A2: 45474 | B2: 12345.67 | C2: =TRUNC(B2) -> 12345
A3: 45475 | B3: 9876.54 | C3: =TRUNC(B3) -> 9876
A4: 45476 | B4: 4567.89 | C4: =TRUNC(B4) -> 4567
A5: 45477 | B5: 11234.56 | C5: =TRUNC(B5) -> 11234
A6: 45478 | B6: 7890.12 | C6: =TRUNC(B6) -> 7890
A7: 45479 | B7: 5432.1 | C7: =TRUNC(B7) -> 5432
A8: 45480 | B8: 6789.34 | C8: =TRUNC(B8) -> 6789

Sheet Retrieving Product Information
A1: Product ID | B1: Product Name | C1: Category | D1: Price
A2: A001 | B2: AI Chatbot | C2: Software | D2: 15000
A3: A002 | B3: AI Analytics | C3: Software | D3: 25000
A4: A003 | B4: Machine Learning | C4: Training | D4: 20000
A5: A004 | B5: Data Processing | C5: Service | D5: 30000
A6: A005 | B6: Image Recognition | C6: Software | D6: 35000
A8: Product ID | B8: Product Name | C8: Category | D8: Price (INR)
A9: A002 | B9: =VLOOKUP(A9,A1:D6,2,FALSE) -> AI Analytics | C9: =VLOOKUP(B9,B1:D6,2,FALSE) -> Software | D9: =VLOOKUP(B9,B1:D6,3,FALSE) -> 25000
A10: A005 | B10: =VLOOKUP(A10,A1:D6,2,FALSE) -> Image Recognition | C10: =VLOOKUP(B10,B1:D6,2,FALSE) -> Software | D10: =VLOOKUP(B10,B1:D6,3,FALSE) -> 35000
A11: A001 | B11: =VLOOKUP(A11,A1:D6,2,FALSE) -> AI Chatbot | C11: =VLOOKUP(B11,B1:D6,2,FALSE) -> Software | D11: =VLOOKUP(B11,B1:D6,3,FALSE) -> 15000

Sheet Extracting Movie Genres
A1: Movie Title | B1: Movie Genre
A2: Avtar-Action | B2: =TRIM(RIGHT(A2,LEN(A2)-FIND("-",A2))) -> Action
A3: Inception-Sci-Fi | B3: =TRIM(RIGHT(A3,LEN(A3)-FIND("-",A3))) -> Sci-Fi
A4: The Dark Knight-Action | B4: =TRIM(RIGHT(A4,LEN(A4)-FIND("-",A4))) -> Action
A5: Titanic-Romance | B5: =TRIM(RIGHT(A5,LEN(A5)-FIND("-",A5))) -> Romance
A6: Interstellar-Sci-Fi | B6: =TRIM(RIGHT(A6,LEN(A6)-FIND("-",A6))) -> Sci-Fi
A7: Joker-Drama | B7: =TRIM(RIGHT(A7,LEN(A7)-FIND("-",A7))) -> Drama
A8: Avengers:Endgame-Action | B8: =TRIM(RIGHT(A8,LEN(A8)-FIND("-",A8))) -> Action
A9: The Lion King-Animation | B9: =TRIM(RIGHT(A9,LEN(A9)-FIND("-",A9))) -> Animation
A10: Bahubali: The Beginning - Action | B10: =TRIM(RIGHT(A10,LEN(A10)-FIND("-",A10))) -> Action
A11: Dangal-Drama | B11: =TRIM(RIGHT(A11,LEN(A11)-FIND("-",A11))) -> Drama

Sheet Server Performance Variance 
A1: Server ID | B1: Day 1 | C1: Day 2 | D1: Day 3 | E1: Day 4 | F1: Day 5 | G1: Day 6 | H1: Day 7 | I1: Response Variance Time
A2: S001 | B2: 120 | C2: 150 | D2: 130 | E2: 140 | F2: 125 | G2: 135 | H2: 145 | I2: =ROUND(_xlfn.VAR.S(B2:H2),2) -> 116.67
A3: S002 | B3: 200 | C3: 210 | D3: 205 | E3: 220 | F3: 215 | G3: 225 | H3: 230 | I3: =ROUND(_xlfn.VAR.S(B3:H3),2) -> 116.67
A4: S003 | B4: 90 | C4: 85 | D4: 95 | E4: 100 | F4: 110 | G4: 105 | H4: 115 | I4: =ROUND(_xlfn.VAR.S(B4:H4),2) -> 116.67
A5: S004 | B5: 180 | C5: 190 | D5: 185 | E5: 195 | F5: 200 | G5: 195 | H5: 205 | I5: =ROUND(_xlfn.VAR.S(B5:H5),2) -> 73.81
A6: S005 | B6: 160 | C6: 170 | D6: 165 | E6: 175 | F6: 180 | G6: 175 | H6: 185 | I6: =ROUND(_xlfn.VAR.S(B6:H6),2) -> 73.81

Sheet Average Transaction Value
A1: Transaction Id | B1: Recharge Amount
A2: T1234 | B2: 150
A3: T5678 | B3: 220
A4: T8901 | B4: 100
A5: T8902 | B5: 110
A6: T9876 | B6: 120
A7: T9843 | B7: 130
A8: T7262 | B8: 145
A9: T7312 | B9: 110
A10: T8112 | B10: 90
A11: T9912 | B11: 76
A12: T0928 | B12: 110
A13: T1233 | B13: 131
A14: T8764 | B14: 100
A16: Answer | B16: =AVERAGE(B2:B14) -> 122.46154

Sheet Discount Offer Management
A1: Product Id | B1: Product Name | C1: Original Price | D1: Discount % | E1: Discounted Price
A2: AJPR001 | B2: Blue Denim Jeans | C2: 1299 | D2: =VLOOKUP(A2,A11:D16,2,FALSE) -> 17 | E2: =C2-D2/100*C2 -> 1078.17
A3: AJPR002 | B3: Floral Printed Dress | C3: 1850 | D3: =VLOOKUP(A3,A12:D17,2,FALSE) -> 18 | E3: =C3-D3/100*C3 -> 1517
A4: AJPR003 | B4: Black Leather Jacket | C4: 3499 | D4: =VLOOKUP(A4,A13:D18,2,FALSE) -> 20 | E4: =C4-D4/100*C4 -> 2799.2
A5: AJPR004 | B5: White Sneakers | C5: 899 | D5: =VLOOKUP(A5,A14:D19,2,FALSE) -> 15 | E5: =C5-D5/100*C5 -> 764.15
A6: AJPR005 | B6: Sports T-Shirt | C6: 549 | D6: =VLOOKUP(A6,A15:D20,2,FALSE) -> 20 | E6: =C6-D6/100*C6 -> 439.2
A11: Product Id | B11: Discount % | C11: Valid From | D11: Valid To
A12: AJPR001 | B12: 17 | C12: 45419 | D12: 45572
A13: AJPR002 | B13: 18 | C13: 45419 | D13: 45572
A14: AJPR003 | B14: 20 | C14: 45419 | D14: 45572
A15: AJPR004 | B15: 15 | C15: 45480 | D15: 45633
A16: AJPR005 | B16: 20 | C16: 45480 | D16: 45633

Sheet Hourly Flight Booking Analysis
A1: Customer Name | B1: Booking Time | C1: Booking Hour
A2: Reliance | B2: 0.4375 | C2: =HOUR(B2) -> 10
A3: TCS | B3: 0.53125 | C3: =HOUR(B3) -> 12
A4: Infosys | B4: 0.59375 | C4: =HOUR(B4) -> 14
A5: HDFC Bank | B5: 0.66666667 | C5: =HOUR(B5) -> 16
A6: ICICI Bank | B6: 0.77083333 | C6: =HOUR(B6) -> 18

Sheet Identifying Invalid Transaction
A1: Transaction ID | B1: Investor Name | C1: Transaction Amount | D1: Valid Transaction?
A2: T001 | B2: Anil Kumar | C2: 5000 | D2: =IF(AND(B2<>0,C2<>0),TRUE,FALSE) -> TRUE
B3: Sneha Sharma | C3: 15000 | D3: =IF(AND(B3<>0,C3<>0),TRUE,FALSE) -> TRUE
A4: T003 | B4: Ajay Singh | D4: =IF(AND(B4<>0,C4<>0),TRUE,FALSE) -> FALSE
A5: T004 | B5: Priya Verma | C5: 12000 | D5: =IF(AND(B5<>0,C5<>0),TRUE,FALSE) -> TRUE
A6: T005 | B6: Rahul Mehta | C6: 3000 | D6: =IF(AND(B6<>0,C6<>0),TRUE,FALSE) -> TRUE
A7: T006 | B7: Anjali Patel | C7: 20000 | D7: =IF(AND(B7<>0,C7<>0),TRUE,FALSE) -> TRUE
A8: T007 | B8: Vivek Anand | C8: 10000 | D8: =IF(AND(B8<>0,C8<>0),TRUE,FALSE) -> TRUE
A9: T008 | B9: Kavita Rao | D9: =IF(AND(B9<>0,C9<>0),TRUE,FALSE) -> FALSE
B10: Manish Tiwari | C10: 2500 | D10: =IF(AND(B10<>0,C10<>0),TRUE,FALSE) -> TRUE
A11: T010 | B11: Pooja Joshi | C11: 18000 | D11: =IF(AND(B11<>0,C11<>0),TRUE,FALSE) -> TRUE

Sheet Identifying the Minimum Order V
A1: Order id | B1: Prooduct Category | C1: Order Value
A2: O001 | B2: Clothing | C2: 1500
A3: O002 | B3: Electronics | C3: 2500
A4: O003 | B4: Home Décor | C4: 1800
A5: O004 | B5: Clothing | C5: 1200
A6: O005 | B6: Electronics | C6: 3000
A7: O006 | B7: Home Décor | C7: 1000
A8: O007 | B8: Clothing | C8: 2000
A9: O008 | B9: Electronics | C9: 1500
A10: O009 | B10: Home Décor | C10: 2000
A11: O010 | B11: Clothing | C11: 1800
A13: Product Category | B13: Minimum Order Value
A14: Clothing | B14: {=MIN(IF($B$2:$B$11="Clothing", $C$2:$C$11))} -> 1200
A15: Electronics | B15: {=MIN(IF($B$2:$B$11="Electronics", $C$2:$C$11))} -> 1500
A16: Home Décor | B16: {=MIN(IF($B$2:$B$11="Home Décor", $C$2:$C$11))} -> 1000

Sheet Updating Travel Package Codes
A1: Package Id | B1: Package Code | C1: Updated Package Code
A2: 1 | B2: IN-OLD-DELHI-2023 | C2: =SUBSTITUTE(B2,"OLD","NEW") -> IN-NEW-DELHI-2023
A3: 2 | B3: IN-OLD-GOA-2023 | C3: =SUBSTITUTE(B3,"OLD","NEW") -> IN-NEW-GOA-2023
A4: 3 | B4: IN-OLD-MUMBAI-2023 | C4: =SUBSTITUTE(B4,"OLD","NEW") -> IN-NEW-MUMBAI-2023
A5: 4 | B5: IN-OLD-KERALA-2023 | C5: =SUBSTITUTE(B5,"OLD","NEW") -> IN-NEW-KERALA-2023
A6: 5 | B6: IN-OLD-AGRA-2023 | C6: =SUBSTITUTE(B6,"OLD","NEW") -> IN-NEW-AGRA-2023

Sheet Analyzing Customer Eligibility 
A1: Customer Id | B1: Customer Name | C1: Number of Rides | D1: Total Spend Last 6 Months | E1: Qualifies for Ola Premium
A2: C001 | B2: Anil Kumar | C2: 45 | D2: 8500 | E2: =IF(AND(C2>=50,D2>=10000),"Yes","No") -> No
A3: C002 | B3: Priya Sharma | C3: 55 | D3: 11200 | E3: =IF(AND(C3>=50,D3>=10000),"Yes","No") -> Yes
A4: C003 | B4: Rohit Verma | C4: 30 | D4: 6000 | E4: =IF(AND(C4>=50,D4>=10000),"Yes","No") -> No
A5: C004 | B5: Sunil Rao | C5: 60 | D5: 12500 | E5: =IF(AND(C5>=50,D5>=10000),"Yes","No") -> Yes
A6: C005 | B6: Rajesh Singh | C6: 25 | D6: 9800 | E6: =IF(AND(C6>=50,D6>=10000),"Yes","No") -> No
A7: C006 | B7: Neha Gupta | C7: 70 | D7: 15000 | E7: =IF(AND(C7>=50,D7>=10000),"Yes","No") -> Yes
A8: C007 | B8: Manish Tiwari | C8: 40 | D8: 7500 | E8: =IF(AND(C8>=50,D8>=10000),"Yes","No") -> No
A9: C008 | B9: Kavita Patel | C9: 20 | D9: 4500 | E9: =IF(AND(C9>=50,D9>=10000),"Yes","No") -> No
A10: C009 | B10: Rakesh Mehra | C10: 65 | D10: 13000 | E10: =IF(AND(C10>=50,D10>=10000),"Yes","No") -> Yes
A11: C010 | B11: Pooja Joshi | C11: 55 | D11: 10500 | E11: =IF(AND(C11>=50,D11>=10000),"Yes","No") -> Yes

Sheet Extract Code and Description
A1: Product Identifier | B1: Product Code | C1: Product Description
A2: 12345-Milk | B2: =TRIM(LEFT(A2,LEN(A2)-FIND("-",A2))) -> 1234 | C2: =TRIM(RIGHT(A2,LEN(A2)-FIND("-",A2))) -> Milk
A3: 67890-Bread | B3: =TRIM(LEFT(A3,LEN(A3)-FIND("-",A3))) -> 67890 | C3: =TRIM(RIGHT(A3,LEN(A3)-FIND("-",A3))) -> Bread
A4: 11223-Eggs | B4: =TRIM(LEFT(A4,LEN(A4)-FIND("-",A4))) -> 1122 | C4: =TRIM(RIGHT(A4,LEN(A4)-FIND("-",A4))) -> Eggs
A5: 33445-Cheese | B5: =TRIM(LEFT(A5,LEN(A5)-FIND("-",A5))) -> 33445- | C5: =TRIM(RIGHT(A5,LEN(A5)-FIND("-",A5))) -> Cheese
A6: 55667-Vegetables | B6: =TRIM(LEFT(A6,LEN(A6)-FIND("-",A6))) -> 55667-Vege | C6: =TRIM(RIGHT(A6,LEN(A6)-FIND("-",A6))) -> Vegetables
A7: 77889-Fruits | B7: =TRIM(LEFT(A7,LEN(A7)-FIND("-",A7))) -> 77889- | C7: =TRIM(RIGHT(A7,LEN(A7)-FIND("-",A7))) -> Fruits
A8: 99000-Meat | B8: =TRIM(LEFT(A8,LEN(A8)-FIND("-",A8))) -> 9900 | C8: =TRIM(RIGHT(A8,LEN(A8)-FIND("-",A8))) -> Meat
A9: 22334-Fish | B9: =TRIM(LEFT(A9,LEN(A9)-FIND("-",A9))) -> 2233 | C9: =TRIM(RIGHT(A9,LEN(A9)-FIND("-",A9))) -> Fish

Sheet Analyzing Product Sales and Inv
A1: Product Id | B1: Product Name | C1: Price | F1: Product Id | G1: Product Name | H1: Inventory
A2: P001 | B2: Aviator | C2: 2000 | F2: P001 | G2: Aviator | H2: 500
A3: P002 | B3: Wayfarer | C3: 1500 | F3: P002 | G3: Wayfarer | H3: 400
A4: P003 | B4: Cat Eye | C4: 1800 | F4: P003 | G4: Cat Eye | H4: 300
A5: P004 | B5: Round | C5: 2200 | F5: P004 | G5: Round | H5: 450
A6: P005 | B6: Rectangle | C6: 1700 | F6: P005 | G6: Rectangle | H6: 350
A8: Month | B8: P001 | C8: P002 | D8: P003 | E8: P004 | F8: P005 | K8: 150
A9: Jan | B9: 150 | C9: 120 | D9: 90 | E9: 110 | F9: 100 | K9: 130
A10: Feb | B10: 130 | C10: 100 | D10: 85 | E10: 105 | F10: 95 | K10: 140
A11: Mar | B11: 140 | C11: 110 | D11: 100 | E11: 120 | F11: 105 | K11: 145
A12: Apr | B12: 145 | C12: 105 | D12: 95 | E12: 115 | F12: 90 | K12: 150
A13: May | B13: 150 | C13: 115 | D13: 110 | E13: 130 | F13: 110 | K13: =SUM(K8:K12) -> 715
A16: Product ID | B16: Price | C16: Total Sales | D16: Inventory | E16: Sales Revenue
A17: P001 | B17: =VLOOKUP(A17,A1:C6,3,FALSE) -> 2000 | C17: =SUM(INDEX(A9:F13, MATCH(A17, A8:F8, 0), 0)) -> 515 | D17: =VLOOKUP(A17,F1:H6,3,FALSE) -> 500 | E17: =C17*D17 -> 257500
A18: P002 | B18: =VLOOKUP(A18,A2:C7,3,FALSE) -> 1500 | C18: =SUM(INDEX(A9:F13, MATCH(A18, A8:F8, 0), 0)) -> 575 | D18: =VLOOKUP(A18,F2:H7,3,FALSE) -> 400 | E18: =C18*D18 -> 230000
A19: P003 | B19: =VLOOKUP(A19,A3:C8,3,FALSE) -> 1800 | C19: =SUM(INDEX(A9:F13, MATCH(A19, A8:F8, 0), 0)) -> 550 | D19: =VLOOKUP(A19,F3:H8,3,FALSE) -> 300 | E19: =C19*D19 -> 165000
A20: P004 | B20: =VLOOKUP(A20,A4:C9,3,FALSE) -> 2200 | C20: =SUM(INDEX(A9:F13,MATCH(A20,A8:F8,0),0)) -> 615 | D20: =VLOOKUP(A20,F4:H9,3,FALSE) -> 450 | E20: =C20*D20 -> 276750
A21: P005 | B21: =VLOOKUP(A21,A5:C10,3,FALSE) -> 1700 | C21: =SUM(INDEX(A8:F13, MATCH(A21, A8:F8, 0), 0)) -> 615 | D21: =VLOOKUP(A21,F5:H10,3,FALSE) -> 350 | E21: =C21*D21 -> 215250

Sheet Inventory and Sales Analysis
A1: Table 1:Inventory Data
A3: Product ID | B3: Product Name | C3: Category | D3: Stock Level | E3: Purchase Price
